#VRML_SIM R2020a utf8
WorldInfo {
}
Viewpoint {
  orientation 0.9816939682397484 0.18117034954169545 0.05877292887576382 5.553690933781533
  position -0.16355879119996009 1.5741692029424936 1.6027280067623477
}
TexturedBackground {
}
TexturedBackgroundLight {
}
footballField {
  length 3
  width 2
  lineThickness 0.01
}
ball {
  translation 0 0.03 0.58
  radius 0.03
  mass 0.05
}
Robot {
  translation 1.28 0 0.2
  rotation 0 0 1 0
  children [
    Transform {
      translation 0 0.095 0
      rotation 0 1 0 3.141592653589793
      children [
        Shape {
          appearance PBRAppearance {
            baseColorMap ImageTexture {
              url [
                "/home/katherine/Desktop/CW/7MSim/protos/robot/caps/jpgCaps/cap0.jpg"
              ]
            }
            roughness 1
            metalness 0
          }
          geometry Cylinder {
            height 0.0001
            radius 0.0675
            subdivision 30
          }
        }
      ]
    }
    Transform {
      translation 0 0.0675 0
      rotation 0 1 0 3.141592653589793
      children [
        cap {
        }
        body {
        }
        bottom {
        }
      ]
    }
    HingeJoint {
      jointParameters HingeJointParameters {
        anchor 0.035 0.02247 0
      }
      device [
        RotationalMotor {
          name "leftMotor"
        }
      ]
      endPoint Solid {
        translation 0 0.0675 0
        rotation 0 0 1 4.6928012867022945e-06
        children [
          Transform {
            rotation 0 1 0 3.141592653589793
            children [
              lWheel {
              }
            ]
          }
        ]
        boundingObject Transform {
          rotation 0 1 0 3.141592653589793
          children [
            lWheel {
            }
          ]
        }
        physics Physics {
        }
      }
    }
    HingeJoint {
      jointParameters HingeJointParameters {
        anchor -0.035 0.02247 0
      }
      device [
        RotationalMotor {
          name "rightMotor"
        }
      ]
      endPoint Solid {
        translation 0 0.0675 0
        rotation 1 0 0 0
        children [
          Transform {
            rotation 0 1 0 3.141592653589793
            children [
              rWheel {
              }
            ]
          }
        ]
        name "solid(1)"
        boundingObject Transform {
          rotation 0 1 0 3.141592653589793
          children [
            rWheel {
            }
          ]
        }
        physics Physics {
        }
      }
    }
    smallWheel {
      translation 0 0.006 0.039
    }
    smallWheel {
      translation 0 0.006 -0.039
    }
  ]
  name "robot(1)"
  boundingObject Group {
    children [
      Transform {
        translation 0 0.0825 0
        children [
          Cylinder {
            height 0.023
            radius 0.0675
            subdivision 30
          }
        ]
      }
      Transform {
        translation 0 0.0675 0
        rotation 0 1 0 3.141592653589793
        children [
          body {
          }
        ]
      }
      Transform {
        translation 0 0.0165 0
        children [
          Box {
            size 0.069 0.001 0.09
          }
        ]
      }
      Transform {
        translation 0 0.006 0.039
        children [
          DEF smallBall Shape {
            geometry Sphere {
              radius 0.006
              subdivision 5
            }
          }
        ]
      }
      Transform {
        translation 0 0.006 -0.039
        children [
          USE smallBall
        ]
      }
    ]
  }
  physics Physics {
    density -1
    mass 0.522
    centerOfMass [
      0 0.053 0
    ]
  }
  controller "robotController"
}
Robot {
  translation 0 10 0
  rotation 1 0 0 -1.5707996938995747
  children [
    Camera {
      fieldOfView 0.3
      width 1024
      height 768
    }
  ]
  controller "cameraController"
}
robot {
}
