#VRML_SIM R2020b utf8
WorldInfo {
  basicTimeStep 25
  coordinateSystem "NUE"
}
Viewpoint {
  orientation -0.6673065209741934 -0.6859907496009212 -0.2900322370483745 1.1294933158041516
  position -4.58056492181821 5.810152747605296 3.880831211837659
}
TexturedBackground {
}
TexturedBackgroundLight {
}
soccerField {
  length 6
  width 4
  lineThickness 0.02
}
DEF Supervisor Robot {
  supervisor TRUE
}
Robot {
  translation 1.56 0.1 -2.31
  rotation 0 0 1 3.141592653589793
  children [
    coloredCap {
    }
    cap {
    }
    Transform {
      translation 0 0.0675 0
      rotation 0 1 0 3.141592653589793
      children [
        body {
        }
      ]
    }
    HingeJoint {
      jointParameters HingeJointParameters {
        anchor 0.047 0.0225 0
      }
      device [
        RotationalMotor {
          name "leftMotor"
          maxVelocity 100
        }
      ]
      endPoint Solid {
        translation 0 0.0675 0
        rotation 1 0 0 0
        children [
          Transform {
            rotation 0 1 0 3.141592653589793
            children [
              lWheel {
              }
            ]
          }
        ]
        boundingObject Transform {
          translation 0.047 -0.045 0
          rotation 0 0 1 1.5707996938995747
          children [
            DEF wheel Cylinder {
              height 0.017
              radius 0.0224
              subdivision 250
            }
          ]
        }
        physics Physics {
        }
      }
    }
    HingeJoint {
      jointParameters HingeJointParameters {
        anchor -0.047 0.0225 0
      }
      device [
        RotationalMotor {
          name "rightMotor"
          maxVelocity 100
        }
      ]
      endPoint Solid {
        translation 0 0.0675 0
        rotation 1 0 0 0
        children [
          Transform {
            rotation 0 1 0 3.141592653589793
            children [
              rWheel {
              }
            ]
          }
        ]
        name "solid(1)"
        boundingObject Transform {
          translation -0.047 -0.045 0
          rotation 0 0 1 1.5707996938995747
          children [
            USE wheel
          ]
        }
        physics Physics {
        }
      }
    }
    smallWheel {
      translation 0 0.006 0.039
    }
    smallWheel {
      translation 0 0.006 -0.039
    }
  ]
  name "robot(1)"
  boundingObject Group {
    children [
      cap {
      }
      Transform {
        translation 0 0.0675 0
        rotation 0 1 0 -3.141592653589793
        children [
          body {
          }
        ]
      }
      Transform {
        translation 0 0.006 0.039
        children [
          DEF smallBall Shape {
            geometry Sphere {
              radius 0.006
              subdivision 5
            }
          }
        ]
      }
      Transform {
        translation 0 0.006 -0.039
        children [
          USE smallBall
        ]
      }
    ]
  }
  physics Physics {
    density -1
    mass 0.522
    centerOfMass [
      0 0.053 0
    ]
  }
}
Robot {
  translation -3.26 0.04 2.12
  children [
    DEF bbody Shape {
      appearance PBRAppearance {
        baseColor 0.4 0.4 0.7
        roughness 1
        metalness 0
      }
      geometry Box {
        size 0.1 0.05 0.2
      }
    }
    HingeJoint {
      jointParameters HingeJointParameters {
        anchor 0.06 0 0.05
      }
      device [
        RotationalMotor {
          name "wheel1"
          maxVelocity 100
        }
      ]
      endPoint Solid {
        translation 0.05999999999999994 0 0.05
        rotation 0 0 1 1.5707996938995745
        children [
          DEF cyl Shape {
            appearance PBRAppearance {
              baseColor 1 0.4 0.4
            }
            geometry Cylinder {
              height 0.02
              radius 0.04
            }
          }
        ]
        boundingObject USE cyl
        physics Physics {
        }
      }
    }
    HingeJoint {
      jointParameters HingeJointParameters {
        anchor -0.06 0 0.05
      }
      device [
        RotationalMotor {
          name "wheel2"
          maxVelocity 100
        }
      ]
      endPoint Solid {
        translation -0.05999999999999994 0 0.05
        rotation 0 0 1 1.5707996938995745
        children [
          USE cyl
        ]
        name "solid(1)"
        boundingObject USE cyl
        physics Physics {
        }
      }
    }
    HingeJoint {
      jointParameters HingeJointParameters {
        anchor 0.06 0 -0.05
      }
      device [
        RotationalMotor {
          name "wheel3"
          maxVelocity 100
        }
      ]
      endPoint Solid {
        translation 0.05999999999999994 0 -0.05
        rotation 0 0 1 1.5707996938995745
        children [
          USE cyl
        ]
        name "solid(2)"
        boundingObject USE cyl
        physics Physics {
        }
      }
    }
    HingeJoint {
      jointParameters HingeJointParameters {
        anchor -0.06 0 -0.05
      }
      device [
        RotationalMotor {
          name "wheel4"
          maxVelocity 100
        }
      ]
      endPoint Solid {
        translation -0.05999999999999994 0 -0.05
        rotation 0 0 1 1.5707996938995745
        children [
          USE cyl
        ]
        name "solid(3)"
        boundingObject USE cyl
        physics Physics {
        }
      }
    }
  ]
  name "robot(2)"
  boundingObject USE bbody
  physics Physics {
  }
  controller "tryController4w"
}
DEF newRobot Robot {
  translation -1.79 0.0675 0.00998568
  rotation 0 1 0 -5.307179586466759e-06
  children [
    coloredCapNew {
    }
    Transform {
      rotation 0 1 0 3.141592653589793
      children [
        capNew {
        }
        body {
        }
      ]
    }
    HingeJoint {
      jointParameters HingeJointParameters {
        anchor -0.047 -0.0455 0
      }
      device [
        RotationalMotor {
          name "wheel1"
          maxVelocity 100
        }
      ]
      endPoint Solid {
        translation -0.047 -0.0455 0
        rotation 0 0 1 1.5707996938995745
        children [
          DEF zzz Shape {
            appearance PBRAppearance {
              roughness 1
              metalness 0
            }
            geometry Cylinder {
              height 0.018
              radius 0.022
              subdivision 50
            }
          }
        ]
        boundingObject USE zzz
        physics Physics {
        }
      }
    }
    HingeJoint {
      jointParameters HingeJointParameters {
        anchor 0.047 -0.0455 0
      }
      device [
        RotationalMotor {
          name "wheel2"
          maxVelocity 100
        }
      ]
      endPoint Solid {
        translation 0.047 -0.0455 0
        rotation 0 0 1 1.5707996938995745
        children [
          USE zzz
        ]
        name "solid(1)"
        boundingObject USE zzz
        physics Physics {
        }
      }
    }
    smallWheel {
      translation 0 -0.0615 -0.039
    }
    smallWheel {
      translation 0 -0.0615 0.039
    }
  ]
  name "robot(6)"
  boundingObject Group {
    children [
      capNew {
      }
      body {
      }
      Transform {
        translation 0 -0.0615 -0.039
        children [
          USE smallBall
        ]
      }
      Transform {
        translation 0 -0.0615 0.039
        children [
          USE smallBall
        ]
      }
    ]
  }
  physics Physics {
    density -1
    mass 0.6
    centerOfMass [
      0 -0.04 0
    ]
  }
  controller "tryController"
}
robotNew {
  translation 2.03 0.0675 0.02
}
